<?xml version="1.0" ?>

<sdf version="1.5">
  <model name="cable_cone">
    <!-- <self_collide>true</self_collide> -->
    <link name='cone'>
      <pose>0 0 0 0 0 0</pose>
      <inertial>
        <mass>0.1</mass>
      </inertial>

      <collision name='base_collision'>
        <geometry>
          <cylinder>
            <radius>0.35</radius>
            <length>0.01</length>
          </cylinder>
        </geometry>
        <surface>
          <friction>
            <ode>
              <mu>1</mu>
              <mu2>1</mu2>
            </ode>
          </friction>
        </surface>
      </collision>

      <visual name='base_visual'>
        <geometry>
          <cylinder>
            <radius>0.35</radius>
            <length>0.01</length>
          </cylinder>
        </geometry>
      </visual>

      <collision name='rod_collision'>
        <pose>0 -0.34 0.75 0 0 0</pose>
        <geometry>
          <cylinder>
            <radius>0.009</radius>
            <length>1.5</length>
          </cylinder>
        </geometry>
      </collision>

      <visual name='rod_visual'>
        <pose>0 -0.34 0.75 0 0 0</pose>
        <geometry>
          <cylinder>
            <radius>0.009</radius>
            <length>1.5</length>
          </cylinder>
        </geometry>
      </visual>

      <sensor name="cone_imu" type="imu">
        <always_on>true</always_on>
        <update_rate>10.0</update_rate>
        <visualize>true</visualize>
        <plugin filename="libgazebo_ros_imu_sensor.so" name="imu_plugin">
          <topicName>imu</topicName>
          <bodyName>cone</bodyName>
          <updateRateHZ>5.0</updateRateHZ>
          <gaussianNoise>0.0</gaussianNoise>
          <xyzOffset>0 0 0</xyzOffset>
          <rpyOffset>0 0 0</rpyOffset>
          <frameName>cone</frameName>
        </plugin>
      </sensor>

      <sensor name="contact_sensor" type="contact">
        <always_on>true</always_on>
        <update_rate>10.0</update_rate>
        <contact>
          <collision>base_collision</collision>
        </contact>
        <plugin filename="libgazebo_ros_bumper.so" name="bumper_plugin">
          <robotNamespace>cable_cone</robotNamespace>
          <updateRateHZ>10.0</updateRateHZ>
          <bumperTopicName>bumper</bumperTopicName>
          <frameName>world</frameName>
        </plugin>
      </sensor>

    </link>

    <link name="mass">
      <pose>0 -0.35 0.5 0 0 0</pose>
      <inertial>
        <mass>1</mass>
      </inertial>

      <collision name='mass_collision'>
        <geometry>
          <cylinder>
            <radius>0.05</radius>
            <length>0.01</length>
          </cylinder>
        </geometry>
      </collision>

      <visual name='mass_visual'>
        <geometry>
          <cylinder>
            <radius>0.05</radius>
            <length>0.01</length>
          </cylinder>
        </geometry>
      </visual>

    </link>

    <joint type="fixed" name="mass_joint">
      <parent>cone</parent>
      <child>mass</child>
    </joint>

    <link name="link0">
      <pose> 0 -0.35500000000000004 1.5 1.57075 0 0</pose>
      <inertial>
        <mass> 0.001 </mass>
        <inertia>
          <ixx>7.599999999999999e-08</ixx>
          <ixy>0.0</ixy>
          <ixz>0.0</ixz>
          <iyy>7.599999999999999e-08</iyy>
          <iyz>0.0</iyz>
          <izz>2.0e-09</izz>
        </inertia>
      </inertial>

      <collision name='link0_collision'>
        <geometry>
          <cylinder>
            <radius>0.002</radius>
            <length>0.03</length>
          </cylinder>
        </geometry>
      </collision>

      <visual name='link0_collision'>
        <geometry>
          <cylinder>
            <radius>0.002</radius>
            <length>0.03</length>
          </cylinder>
        </geometry>
      </visual>
    </link>

    <joint name="joint0" type="universal">
      <pose>0 0 -0.015 0 0 0</pose>
      <parent>cone</parent>
      <child>link0</child>
    </joint>

    
    <link name="link1">
      <pose> 0 -0.385 1.5 1.57075 0 0</pose>
      <inertial>
        <mass> 0.001 </mass>
        <inertia>
          <ixx>7.599999999999999e-08</ixx>
          <ixy>0.0</ixy>
          <ixz>0.0</ixz>
          <iyy>7.599999999999999e-08</iyy>
          <iyz>0.0</iyz>
          <izz>2.0e-09</izz>
        </inertia>
      </inertial>

      <collision name='link1_collision'>
        <geometry>
          <cylinder>
            <radius>0.002</radius>
            <length>0.03</length>
          </cylinder>
        </geometry>
      </collision>

      <visual name='link1_collision'>
        <geometry>
          <cylinder>
            <radius>0.002</radius>
            <length>0.03</length>
          </cylinder>
        </geometry>
      </visual>
    </link>

    <joint name="joint1" type="universal">
      <pose>0 0 -0.015 0 0 0</pose>
      <parent>link0</parent>
      <child>link1</child>
    </joint>

    
    <link name="link2">
      <pose> 0 -0.41500000000000004 1.5 1.57075 0 0</pose>
      <inertial>
        <mass> 0.001 </mass>
        <inertia>
          <ixx>7.599999999999999e-08</ixx>
          <ixy>0.0</ixy>
          <ixz>0.0</ixz>
          <iyy>7.599999999999999e-08</iyy>
          <iyz>0.0</iyz>
          <izz>2.0e-09</izz>
        </inertia>
      </inertial>

      <collision name='link2_collision'>
        <geometry>
          <cylinder>
            <radius>0.002</radius>
            <length>0.03</length>
          </cylinder>
        </geometry>
      </collision>

      <visual name='link2_collision'>
        <geometry>
          <cylinder>
            <radius>0.002</radius>
            <length>0.03</length>
          </cylinder>
        </geometry>
      </visual>
    </link>

    <joint name="joint2" type="universal">
      <pose>0 0 -0.015 0 0 0</pose>
      <parent>link1</parent>
      <child>link2</child>
    </joint>

    
    <link name="link3">
      <pose> 0 -0.44500000000000006 1.5 1.57075 0 0</pose>
      <inertial>
        <mass> 0.001 </mass>
        <inertia>
          <ixx>7.599999999999999e-08</ixx>
          <ixy>0.0</ixy>
          <ixz>0.0</ixz>
          <iyy>7.599999999999999e-08</iyy>
          <iyz>0.0</iyz>
          <izz>2.0e-09</izz>
        </inertia>
      </inertial>

      <collision name='link3_collision'>
        <geometry>
          <cylinder>
            <radius>0.002</radius>
            <length>0.03</length>
          </cylinder>
        </geometry>
      </collision>

      <visual name='link3_collision'>
        <geometry>
          <cylinder>
            <radius>0.002</radius>
            <length>0.03</length>
          </cylinder>
        </geometry>
      </visual>
    </link>

    <joint name="joint3" type="universal">
      <pose>0 0 -0.015 0 0 0</pose>
      <parent>link2</parent>
      <child>link3</child>
    </joint>

    
    <link name="link4">
      <pose> 0 -0.47500000000000003 1.5 1.57075 0 0</pose>
      <inertial>
        <mass> 0.001 </mass>
        <inertia>
          <ixx>7.599999999999999e-08</ixx>
          <ixy>0.0</ixy>
          <ixz>0.0</ixz>
          <iyy>7.599999999999999e-08</iyy>
          <iyz>0.0</iyz>
          <izz>2.0e-09</izz>
        </inertia>
      </inertial>

      <collision name='link4_collision'>
        <geometry>
          <cylinder>
            <radius>0.002</radius>
            <length>0.03</length>
          </cylinder>
        </geometry>
      </collision>

      <visual name='link4_collision'>
        <geometry>
          <cylinder>
            <radius>0.002</radius>
            <length>0.03</length>
          </cylinder>
        </geometry>
      </visual>
    </link>

    <joint name="joint4" type="universal">
      <pose>0 0 -0.015 0 0 0</pose>
      <parent>link3</parent>
      <child>link4</child>
    </joint>

    
    <link name="link5">
      <pose> 0 -0.505 1.5 1.57075 0 0</pose>
      <inertial>
        <mass> 0.001 </mass>
        <inertia>
          <ixx>7.599999999999999e-08</ixx>
          <ixy>0.0</ixy>
          <ixz>0.0</ixz>
          <iyy>7.599999999999999e-08</iyy>
          <iyz>0.0</iyz>
          <izz>2.0e-09</izz>
        </inertia>
      </inertial>

      <collision name='link5_collision'>
        <geometry>
          <cylinder>
            <radius>0.002</radius>
            <length>0.03</length>
          </cylinder>
        </geometry>
      </collision>

      <visual name='link5_collision'>
        <geometry>
          <cylinder>
            <radius>0.002</radius>
            <length>0.03</length>
          </cylinder>
        </geometry>
      </visual>
    </link>

    <joint name="joint5" type="universal">
      <pose>0 0 -0.015 0 0 0</pose>
      <parent>link4</parent>
      <child>link5</child>
    </joint>

    
    <link name="link6">
      <pose> 0 -0.535 1.5 1.57075 0 0</pose>
      <inertial>
        <mass> 0.001 </mass>
        <inertia>
          <ixx>7.599999999999999e-08</ixx>
          <ixy>0.0</ixy>
          <ixz>0.0</ixz>
          <iyy>7.599999999999999e-08</iyy>
          <iyz>0.0</iyz>
          <izz>2.0e-09</izz>
        </inertia>
      </inertial>

      <collision name='link6_collision'>
        <geometry>
          <cylinder>
            <radius>0.002</radius>
            <length>0.03</length>
          </cylinder>
        </geometry>
      </collision>

      <visual name='link6_collision'>
        <geometry>
          <cylinder>
            <radius>0.002</radius>
            <length>0.03</length>
          </cylinder>
        </geometry>
      </visual>
    </link>

    <joint name="joint6" type="universal">
      <pose>0 0 -0.015 0 0 0</pose>
      <parent>link5</parent>
      <child>link6</child>
    </joint>

    
    <link name="link7">
      <pose> 0 -0.5650000000000001 1.5 1.57075 0 0</pose>
      <inertial>
        <mass> 0.001 </mass>
        <inertia>
          <ixx>7.599999999999999e-08</ixx>
          <ixy>0.0</ixy>
          <ixz>0.0</ixz>
          <iyy>7.599999999999999e-08</iyy>
          <iyz>0.0</iyz>
          <izz>2.0e-09</izz>
        </inertia>
      </inertial>

      <collision name='link7_collision'>
        <geometry>
          <cylinder>
            <radius>0.002</radius>
            <length>0.03</length>
          </cylinder>
        </geometry>
      </collision>

      <visual name='link7_collision'>
        <geometry>
          <cylinder>
            <radius>0.002</radius>
            <length>0.03</length>
          </cylinder>
        </geometry>
      </visual>
    </link>

    <joint name="joint7" type="universal">
      <pose>0 0 -0.015 0 0 0</pose>
      <parent>link6</parent>
      <child>link7</child>
    </joint>

    
    <link name="link8">
      <pose> 0 -0.595 1.5 1.57075 0 0</pose>
      <inertial>
        <mass> 0.001 </mass>
        <inertia>
          <ixx>7.599999999999999e-08</ixx>
          <ixy>0.0</ixy>
          <ixz>0.0</ixz>
          <iyy>7.599999999999999e-08</iyy>
          <iyz>0.0</iyz>
          <izz>2.0e-09</izz>
        </inertia>
      </inertial>

      <collision name='link8_collision'>
        <geometry>
          <cylinder>
            <radius>0.002</radius>
            <length>0.03</length>
          </cylinder>
        </geometry>
      </collision>

      <visual name='link8_collision'>
        <geometry>
          <cylinder>
            <radius>0.002</radius>
            <length>0.03</length>
          </cylinder>
        </geometry>
      </visual>
    </link>

    <joint name="joint8" type="universal">
      <pose>0 0 -0.015 0 0 0</pose>
      <parent>link7</parent>
      <child>link8</child>
    </joint>

    
    <link name="link9">
      <pose> 0 -0.625 1.5 1.57075 0 0</pose>
      <inertial>
        <mass> 0.001 </mass>
        <inertia>
          <ixx>7.599999999999999e-08</ixx>
          <ixy>0.0</ixy>
          <ixz>0.0</ixz>
          <iyy>7.599999999999999e-08</iyy>
          <iyz>0.0</iyz>
          <izz>2.0e-09</izz>
        </inertia>
      </inertial>

      <collision name='link9_collision'>
        <geometry>
          <cylinder>
            <radius>0.002</radius>
            <length>0.03</length>
          </cylinder>
        </geometry>
      </collision>

      <visual name='link9_collision'>
        <geometry>
          <cylinder>
            <radius>0.002</radius>
            <length>0.03</length>
          </cylinder>
        </geometry>
      </visual>
    </link>

    <joint name="joint9" type="universal">
      <pose>0 0 -0.015 0 0 0</pose>
      <parent>link8</parent>
      <child>link9</child>
    </joint>

    

    <link name="ring">
      <pose>0 -0.66 1.5 0 0 0</pose>
      <inertial>
        <mass>0.005</mass>
         <inertia>
          <ixx>1.0000000000000002e-06</ixx>
          <ixy>0.0</ixy>
          <ixz>0.0</ixz>
          <iyy>1.0000000000000002e-06</iyy>
          <iyz>0.0</iyz>
          <izz>2.0000000000000003e-06</izz>
        </inertia>
      </inertial>

      <collision name="ring_collision">
        <geometry>
          <mesh>
            <uri>model://cable_cone/meshes/ring.stl</uri>
          </mesh>
        </geometry>
      </collision>

      <visual name="ring_visual">
        <geometry>
          <mesh>
            <uri>model://cable_cone/meshes/ring.dae</uri>
          </mesh>
        </geometry>
      </visual>
    </link>

    <joint name="ring_joint" type="universal">
      <pose>0 0.02 0 0 0 0</pose>
      <parent>link9</parent>
      <child>ring</child>
    </joint>

  </model>
</sdf>
