<?xml version="1.0" ?>
<%
  # Cone with cable connected
  # Consists of cone link to a ring formed by small cylinder element
  # SI units (length in meters, weight in kg)

  #Geometry
  pi = 3.1415
  cable_length = 0.3
  cylinder_radius = 0.002
  element_qty = 10
  cylinder_length = cable_length/element_qty
  ring_radius = 0.02
  #Inertia
  cable_mass = 0.01
  element_mass = cable_mass/element_qty
  cylinder_ixx = element_mass/12 * cylinder_length * cylinder_length + element_mass/4 * cylinder_radius * cylinder_radius
  cylinder_izz = element_mass/2 * cylinder_radius * cylinder_radius
  ring_mass = 0.005
  ring_ixx = ring_mass/2 * ring_radius * ring_radius
  ring_izz = ring_mass * ring_radius * ring_radius
  #Cable Joint Property
  cable_joint_damping = 10.0
  cable_joint_friction = 0.0
  #Anchor Point
  anchor_x = 0
  anchor_y = -0.3525
  anchor_z = 1.4

%>
<sdf version="1.5">
  <model name="cable_cone">
    <!-- <self_collide>true</self_collide> -->

    <include>
      <uri>model://experimental_cone</uri>
      <pose> 0 0 0 0 0 0 </pose>
    </include>

    <link name="link0">
      <pose> <%= anchor_x %> <%= anchor_y - cylinder_length/2%> <%= anchor_z %> <%=  pi/2 %> 0 0</pose>
      <inertial>
        <mass> <%= element_mass %> </mass>
        <inertia>
          <ixx><%= cylinder_ixx %></ixx>
          <ixy>0.0</ixy>
          <ixz>0.0</ixz>
          <iyy><%= cylinder_ixx %></iyy>
          <iyz>0.0</iyz>
          <izz><%= cylinder_izz %></izz>
        </inertia>
      </inertial>

      <collision name='link0_collision'>
        <geometry>
          <cylinder>
            <radius><%= cylinder_radius %></radius>
            <length><%= cylinder_length %></length>
          </cylinder>
        </geometry>
      </collision>

      <visual name='link0_collision'>
        <geometry>
          <cylinder>
            <radius><%= cylinder_radius %></radius>
            <length><%= cylinder_length %></length>
          </cylinder>
        </geometry>
        <material>
          <script>
            <uri>file://media/materials/scripts/gazebo.material</uri>
            <name>Gazebo/Black</name>
          </script>
        </material>
      </visual>
    </link>

    <joint name="joint0" type="universal">
      <pose>0 0 <%= -cylinder_length/2%> 0 0 0</pose>
      <parent>experimental_cone::cone</parent>
      <child>link0</child>
    </joint>

    <% for i in 1..element_qty-1 do %>
    <link name="link<%= i %>">
      <pose> <%= anchor_x %> <%= anchor_y - cylinder_length/2 - i*cylinder_length %> <%= anchor_z %> <%=  pi/2 %> 0 0</pose>
      <inertial>
        <mass> <%= element_mass %> </mass>
        <inertia>
          <ixx><%= cylinder_ixx %></ixx>
          <ixy>0.0</ixy>
          <ixz>0.0</ixz>
          <iyy><%= cylinder_ixx %></iyy>
          <iyz>0.0</iyz>
          <izz><%= cylinder_izz %></izz>
        </inertia>
      </inertial>

      <collision name='link<%= i %>_collision'>
        <geometry>
          <cylinder>
            <radius><%= cylinder_radius %></radius>
            <length><%= cylinder_length %></length>
          </cylinder>
        </geometry>
      </collision>

      <visual name='link<%= i %>_collision'>
        <geometry>
          <cylinder>
            <radius><%= cylinder_radius %></radius>
            <length><%= cylinder_length %></length>
          </cylinder>
        </geometry>
        <material>
          <script>
            <uri>file://media/materials/scripts/gazebo.material</uri>
            <name>Gazebo/Black</name>
          </script>
        </material>
      </visual>
    </link>

    <joint name="joint<%= i %>" type="universal">
      <pose>0 0 <%= -cylinder_length/2 %> 0 0 0</pose>
      <parent>link<%= i-1 %></parent>
      <child>link<%= i %></child>
    </joint>

    <%end%>

    <link name="ring">
      <pose><%= anchor_x %> <%= anchor_y - element_qty*cylinder_length - ring_radius%> <%= anchor_z%> 0 0 0</pose>
      <inertial>
        <mass><%=ring_mass%></mass>
         <inertia>
          <ixx><%= ring_ixx %></ixx>
          <ixy>0.0</ixy>
          <ixz>0.0</ixz>
          <iyy><%= ring_ixx %></iyy>
          <iyz>0.0</iyz>
          <izz><%= ring_izz %></izz>
        </inertia>
      </inertial>

      <collision name="ring_collision">
        <geometry>
          <mesh>
            <uri>model://cable_cone/meshes/ring.stl</uri>
          </mesh>
        </geometry>
      </collision>

      <visual name="ring_visual">
        <geometry>
          <mesh>
            <uri>model://cable_cone/meshes/ring.dae</uri>
          </mesh>
        </geometry>
      </visual>
    </link>

    <joint name="ring_joint" type="universal">
      <pose>0 <%=ring_radius%> 0 0 0 0 </pose>
      <parent>link<%= element_qty-1%></parent>
      <child>ring</child>
    </joint>

  </model>
</sdf>
